Workbook

Sheet Colgate IS
A1: Colgate-Palmolive Income Statement | G1: Historicals | J1: Forecasts
A3: (all data in ₹ lakhs) | G3: 2023 | H3: 2024 | I3: 2025 | J3: 2026 | K3: 2027 | L3: 2028 | M3: 2029 | N3: 2030
A4: Revenue from Operations | G4: 522619.71 | H4: 568043 | I4: 604017 | J4: =I4*(1+J25) -> 652338.36 | K4: =J4*(1+K25) -> 704525.43 | L4: =K4*(1+L25) -> 760887.46 | M4: =L4*(1+M25) -> 821758.46 | N4: =M4*(1+N25) -> 887499.14
A5: Other Income | G5: 5357.59 | H5: 7652 | I5: 13884 | J5: =I5*(1+J26) -> 14092.26 | K5: =J5*(1+K26) -> 14303.644 | L5: =K5*(1+L26) -> 14518.199 | M5: =L5*(1+M26) -> 14735.972 | N5: =M5*(1+N26) -> 14957.011
A6: (A) Total Income | G6: =SUM(G4:G5) -> 527977.3 | H6: =SUM(H4:H5) -> 575695 | I6: =SUM(I4:I5) -> 617901 | J6: =SUM(J4:J5) -> 666430.62 | K6: =SUM(K4:K5) -> 718829.07 | L6: =SUM(L4:L5) -> 775405.66 | M6: =SUM(M4:M5) -> 836494.43 | N6: =SUM(N4:N5) -> 902456.15
A7: Expenses
A8: Cost of Material Consumed | G8: 149249.58 | H8: 145758.73 | I8: 157911 | J8: =J29*J4 -> 169607.97 | K8: =K29*K4 -> 183176.61 | L8: =L29*L4 -> 197830.74 | M8: =M29*M4 -> 213657.2 | N8: =N29*N4 -> 230749.78
A9: Purchase of Stock-in-Trade | G9: 29776.86 | H9: 24491.33 | I9: 30986 | J9: =J30*J4 -> 32616.918 | K9: =K30*K4 -> 35226.271 | L9: =L30*L4 -> 38044.373 | M9: =M30*M4 -> 41087.923 | N9: =N30*N4 -> 44374.957
A10: Changes in Inventories | G10: 391.94 | H10: 2048 | I10: -7070 | J10: ='Working Capital'!H7-'Working Capital'!I7 -> -502.81512 | K10: ='Working Capital'!I7-'Working Capital'!J7 -> -3058.3052 | L10: ='Working Capital'!J7-'Working Capital'!K7 -> -3302.9696 | M10: ='Working Capital'!K7-'Working Capital'!L7 -> -3567.2072 | N10: ='Working Capital'!L7-'Working Capital'!M7 -> -3852.5838
A11: Employee Benefits Expense | G11: 37696.99 | H11: 41173 | I11: 44678 | J11: =J31*J4 -> 45663.685 | K11: =J11*(1+K31) -> 48860.143 | L11: =K11*(1+L31) -> 52280.353 | M11: =L11*(1+M31) -> 55939.978 | N11: =M11*(1+N31) -> 59855.776
A12: Other Expenses | G12: 150802 | H12: 164490 | I12: 181706 | J12: =J32*J4 -> 182654.74 | K12: =K32*K4 -> 197267.12 | L12: =L32*L4 -> 213048.49 | M12: =M32*M4 -> 230092.37 | N12: =N32*N4 -> 248499.76
A13: (B) Total Expense | G13: =SUM(G8:G12) -> 367917.37 | H13: =SUM(H8:H12) -> 377961.06 | I13: =SUM(I8:I12) -> 408211 | J13: =SUM(J8:J12) -> 430040.5 | K13: =SUM(K8:K12) -> 461471.84 | L13: =SUM(L8:L12) -> 497900.99 | M13: =SUM(M8:M12) -> 537210.26 | N13: =SUM(N8:N12) -> 579627.68
A14: Profit Before Exceptional Item and Tax | G14: =G6-G13 -> 160059.93 | H14: =H6-H13 -> 197733.94 | I14: =I6-I13 -> 209690 | J14: =J6-J13 -> 236390.12 | K14: =K6-K13 -> 257357.23 | L14: =L6-L13 -> 277504.67 | M14: =M6-M13 -> 299284.17 | N14: =N6-N13 -> 322828.46
A15: Exceptional Items | G15: 1120.87 | H15: 1950.2 | I15: 0 | J15: 0 | K15: 0 | L15: 0 | M15: 0 | N15: 0
A16: (C) EBITDA | G16: =G14-G15 -> 158939.06 | H16: =H14-H15 -> 195783.74 | I16: =I6-I13 -> 209690 | J16: =J14-J15 -> 236390.12 | K16: =K14-K15 -> 257357.23 | L16: =L14-L15 -> 277504.67 | M16: =M14-M15 -> 299284.17 | N16: =N14-N15 -> 322828.46
A17: Depreciation and Amortisation | G17: 17480.37 | H17: 17151.05 | I17: 16274 | J17: ='Dep Capex'!I12 -> 13199.82 | K17: ='Dep Capex'!J12 -> 12397.518 | L17: ='Dep Capex'!K12 -> 11846.941 | M17: ='Dep Capex'!L12 -> 11546.608 | N17: ='Dep Capex'!M12 -> 11399.771
A18: (D) EBIT | G18: =G16-G17 -> 141458.69 | H18: =H16-H17 -> 178632.69 | I18: =I16-I17 -> 193416 | J18: =J16-J17 -> 223190.3 | K18: =K16-K17 -> 244959.71 | L18: =L16-L17 -> 265657.73 | M18: =M16-M17 -> 287737.56 | N18: =N16-N17 -> 311428.69
A19: Finance Cost | G19: 491.38 | H19: 499.63 | I19: 432 | J19: =J4*J34 -> 554.48761 | K19: =K4*K34 -> 598.84661 | L19: =L4*L34 -> 646.75434 | M19: =M4*M34 -> 698.49469 | N19: =N4*N34 -> 754.37427
A20: (E) PBT | G20: =G18-G19 -> 140967.31 | H20: =H18-H19 -> 178133.06 | I20: =I18-I19 -> 192984 | J20: =J18-J19 -> 222635.81 | K20: =K18-K19 -> 244360.87 | L20: =L18-L19 -> 265010.98 | M20: =M18-M19 -> 287039.07 | N20: =N18-N19 -> 310674.32
A21: Total Tax Expense | G21: 36252.62 | H21: 45766.56 | I21: 49303 | J21: =J20*J35 -> 56772.132 | K21: =K20*K35 -> 62312.021 | L21: =L20*L35 -> 67577.8 | M21: =M20*M35 -> 73194.962 | N21: =N20*N35 -> 79221.952
A22: PAT | G22: =G20-G21 -> 104714.69 | H22: =H20-H21 -> 132366.5 | I22: =I20-I21 -> 143681 | J22: =J20-J21 -> 165863.68 | K22: =K20-K21 -> 182048.85 | L22: =L20-L21 -> 197433.18 | M22: =M20-M21 -> 213844.1 | N22: =N20-N21 -> 231452.37
A24: Drivers
A25: Revenue % growth | H25: =H4/G4-1 -> 0.086914613 | I25: =I4/H4-1 -> 0.063329713 | J25: 0.08 | K25: 0.08 | L25: 0.08 | M25: 0.08 | N25: 0.08
A26: other income | G26: =G5/G4 -> 0.010251412 | H26: =H5/H4 -> 0.013470811 | I26: =I5/I4 -> 0.022986108 | J26: 0.015 | K26: 0.015 | L26: 0.015 | M26: 0.015 | N26: 0.015
A28: Expenses ( as % of Revenue)
A29: Cost of Material Consumed | G29: =G8/G4 -> 0.2855797 | H29: =H8/H4 -> 0.25659806 | I29: =I8/I4 -> 0.26143469 | J29: 0.26 | K29: 0.26 | L29: 0.26 | M29: 0.26 | N29: 0.26
A30: Purchase of Stock-in-Trade | G30: =G9/G4 -> 0.056976152 | H30: =H9/H4 -> 0.043115275 | I30: =I9/I4 -> 0.051299881 | J30: 0.05 | K30: 0.05 | L30: 0.05 | M30: 0.05 | N30: 0.05
A31: Employee Benefits Expense | G31: =G11/G4 -> 0.072130823 | H31: =H11/H4 -> 0.072482189 | I31: =I11/I4 -> 0.073968117 | J31: 0.07 | K31: 0.07 | L31: 0.07 | M31: 0.07 | N31: 0.07
A32: Other Expenses | G32: =G12/G4 -> 0.28855016 | H32: =H12/H4 -> 0.28957315 | I32: =I12/I4 -> 0.30082928 | J32: 0.28 | K32: 0.28 | L32: 0.28 | M32: 0.28 | N32: 0.28
A34: Finance Cost as % of Revenue | G34: =G19/G4 -> 0.00094022478 | H34: =H19/H4 -> 0.0008795637 | I34: =I19/I4 -> 0.00071521166 | J34: 0.00085 | K34: 0.00085 | L34: 0.00085 | M34: 0.00085 | N34: 0.00085
A35: Tax % | G35: =G21/G20 -> 0.2571704 | H35: =H21/H20 -> 0.25692345 | I35: =I21/I20 -> 0.25547714 | J35: 0.255 | K35: 0.255 | L35: 0.255 | M35: 0.255 | N35: 0.255

Sheet Colgate BS
A1: Colgate-Palmolive Balance Sheet | F1: Historicals | I1: Forecasts
A3: (all data in ₹ Lakhs) | F3: 2023 | G3: 2024 | H3: 2025 | I3: 2026 | J3: 2027 | K3: 2028 | L3: 2029 | M3: 2030
A4: Assets
A5: Non-Current Assets
A6: Property, Plant and Equipment | F6: 86179.92 | G6: 79407 | H6: 77646 | I6: ='Dep Capex'!I13 -> 72926.579 | J6: ='Dep Capex'!J13 -> 69687.891 | K6: ='Dep Capex'!K13 -> 67921.223 | L6: ='Dep Capex'!L13 -> 67057.475 | M6: ='Dep Capex'!M13 -> 67195.193
A7: Capital Work-in-Progress | F7: 11407.68 | G7: 11028 | H7: 3841 | I7: =CWIP!B9 -> 1272.0598 | J7: =CWIP!C9 -> 1373.8246 | K7: =CWIP!D9 -> 1512.041 | L7: =CWIP!E9 -> 1602.429 | M7: =CWIP!F9 -> 1730.6233
A8: Financial Assets
A9: (i) Loans | F9: 92.02 | G9: 97 | H9: 120 | I9: =FA!C6 -> 126 | J9: =FA!D6 -> 132.3 | K9: =FA!E6 -> 138.915 | L9: =FA!F6 -> 145.86075 | M9: =FA!G6 -> 153.15379
A10: (ii) Other financial assets | F10: 1853.97 | G10: 1682 | H10: 1783 | I10: =FA!C9 -> 1872.15 | J10: =FA!D9 -> 1965.7575 | K10: =FA!E9 -> 2064.0454 | L10: =FA!F9 -> 2167.2476 | M10: =FA!G9 -> 2275.61
A11: Deferred Tax Assets (Net) | F11: 2884.26 | G11: 6476 | H11: 6795 | I11: =H11*(1+I55) -> 7066.8 | J11: =I11*(1+J55) -> 7349.472 | K11: =J11*(1+K55) -> 7643.4509 | L11: =K11*(1+L55) -> 7949.1889 | M11: =L11*(1+M55) -> 8267.1565
A12: Other Non-Current Assets | F12: 1303.74 | G12: 793 | H12: 897 | I12: =H12*(1+I56) -> 941.85 | J12: =I12*(1+J56) -> 988.9425 | K12: =J12*(1+K56) -> 1038.3896 | L12: =K12*(1+L56) -> 1090.3091 | M12: =L12*(1+M56) -> 1144.8246
A13: Current Tax Assets (Net) | F13: 29788.98 | G13: 29789 | H13: 34502 | I13: =H13*(1+I57) -> 37262.16 | J13: =I13*(1+J57) -> 40243.133 | K13: =J13*(1+K57) -> 43462.583 | L13: =K13*(1+L57) -> 46939.59 | M13: =L13*(1+M57) -> 50694.757
F14: =SUM(F6:F13) -> 133510.57 | G14: =SUM(G6:G13) -> 129272 | H14: =SUM(H6:H13) -> 125584 | I14: =SUM(I6:I13) -> 121467.6 | J14: =SUM(J6:J13) -> 121741.32 | K14: =SUM(K6:K13) -> 123780.65 | L14: =SUM(L6:L13) -> 126952.1 | M14: =SUM(M6:M13) -> 131461.32
A15: Current Assets
A16: Inventories | F16: 33544.96 | G16: 29641 | H16: 37726 | I16: ='Working Capital'!I7 -> 38228.815 | J16: ='Working Capital'!J7 -> 41287.12 | K16: ='Working Capital'!K7 -> 44590.09 | L16: ='Working Capital'!L7 -> 48157.297 | M16: ='Working Capital'!M7 -> 52009.881
A17: Financial Assets
A18: (i) Trade Receivables | F18: 15736.61 | G18: 16739 | H18: 22625 | I18: ='Working Capital'!I6 -> 21446.741 | J18: ='Working Capital'!J6 -> 23162.48 | K18: ='Working Capital'!K6 -> 25015.478 | L18: ='Working Capital'!L6 -> 27016.716 | M18: ='Working Capital'!M6 -> 29178.054
A19: (ii) Cash and Cash Equivalents | F19: 80605.68 | G19: 88899 | H19: 66810 | I19: ='Colgate CF'!F27 -> 88111.537 | J19: ='Colgate CF'!G27 -> 120532 | K19: ='Colgate CF'!H27 -> 153938.04 | L19: ='Colgate CF'!I27 -> 189064.76 | M19: ='Colgate CF'!J27 -> 226006.16
A20: (iii) Bank Balances [other than (ii) above] | F20: 11693.84 | G20: 48479 | H20: 42703 | I20: =I63 -> 44248 | J20: =J63 -> 43069 | K20: =K63 -> 41794 | L20: =L63 -> 40502 | M20: =M63 -> 39099
A21: (iv) Loans | F21: 8759.91 | G21: 667 | H21: 667 | I21: 667 | J21: 667 | K21: 667 | L21: 667 | M21: 667
A22: (v) Other financial assets | F22: 636.09 | G22: 602 | H22: 648 | I22: =H22*(1+I61) -> 680.4 | J22: =I22*(1+J61) -> 714.42 | K22: =J22*(1+K61) -> 750.141 | L22: =K22*(1+L61) -> 787.64805 | M22: =L22*(1+M61) -> 827.03045
A23: Other Current Assets | F23: 3811.27 | G23: 5354 | H23: 5092 | I23: =H23*(1+I62) -> 5499.36 | J23: =I23*(1+J62) -> 5939.3088 | K23: =J23*(1+K62) -> 6414.4535 | L23: =K23*(1+L62) -> 6927.6098 | M23: =L23*(1+M62) -> 7481.8186
F24: =SUM(F16:F23) -> 154788.36 | G24: =SUM(G16:G23) -> 190381 | H24: =SUM(H16:H23) -> 176271 | I24: =SUM(I16:I23) -> 198881.85 | J24: =SUM(J16:J23) -> 235371.33 | K24: =SUM(K16:K23) -> 273169.21 | L24: =SUM(L16:L23) -> 313123.03 | M24: =SUM(M16:M23) -> 355268.94
A25: Total Assets | F25: =SUM(F14,F24) -> 288298.93 | G25: =SUM(G14,G24) -> 319653 | H25: =SUM(H14,H24) -> 301855 | I25: =SUM(I14,I24) -> 320349.45 | J25: =SUM(J14,J24) -> 357112.65 | K25: =SUM(K14,K24) -> 396949.85 | L25: =SUM(L14,L24) -> 440075.13 | M25: =SUM(M14,M24) -> 486730.26
A27: Equity and Liabilities
A28: Equity
A29: Equity Share Capital | F29: 2720 | G29: 2720 | H29: 2720 | I29: 2720 | J29: 2720 | K29: 2720 | L29: 2720 | M29: 2720
A30: Other Equity | F30: 168919 | G30: 184716 | H30: 163727 | I30: =Equity!B8 -> 188606.55 | J30: =Equity!C8 -> 215913.88 | K30: =Equity!D8 -> 245528.86 | L30: =Equity!E8 -> 277605.47 | M30: =Equity!F8 -> 312323.33
A31: Total Equity | F31: =SUM(F29,F30) -> 171639 | G31: =SUM(G29,G30) -> 187436 | H31: =SUM(H29,H30) -> 166447 | I31: =I29+I30 -> 191326.55 | J31: =J29+J30 -> 218633.88 | K31: =K29+K30 -> 248248.86 | L31: =L29+L30 -> 280325.47 | M31: =M29+M30 -> 315043.33
A33: Liabilities
A34: Non-current liabilities
A35: Financial Liabilities
A36: (i) Lease liabilities | F36: 5674 | G36: 5955 | H36: 4543 | I36: =H36*(1+I73) -> 4315.85 | J36: =I36*(1+J73) -> 4100.0575 | K36: =J36*(1+K73) -> 3895.0546 | L36: =K36*(1+L73) -> 3700.3019 | M36: =L36*(1+M73) -> 3515.2868
A37: (ii) Other Financial Liabilities | F37: 124 | G37: 130 | H37: 130 | I37: =H37*(1+I76) -> 135.2 | J37: =I37*(1+J76) -> 140.608 | K37: =J37*(1+K76) -> 146.23232 | L37: =K37*(1+L76) -> 152.08161 | M37: =L37*(1+M76) -> 158.16488
A38: Provisions | F38: 2359 | G38: 2161 | H38: 2991 | I38: =H38*(1+I77) -> 3200.37 | J38: =I38*(1+J77) -> 3424.3959 | K38: =J38*(1+K77) -> 3664.1036 | L38: =K38*(1+L77) -> 3920.5909 | M38: =L38*(1+M77) -> 4195.0322
A39: Other Non-Current Liabilities | F39: 40 | G39: 36 | H39: 30 | I39: =H39*(1+I78) -> 28.5 | J39: =I39*(1+J78) -> 27.075 | K39: =J39*(1+K78) -> 25.72125 | L39: =K39*(1+L78) -> 24.435187 | M39: =L39*(1+M78) -> 23.213428
F40: =SUM(F36:F39) -> 8197 | G40: =SUM(G36:G39) -> 8282 | H40: =SUM(H36:H39) -> 7694 | I40: =SUM(I36:I39) -> 7679.92 | J40: =SUM(J36:J39) -> 7692.1364 | K40: =SUM(K36:K39) -> 7731.1118 | L40: =SUM(L36:L39) -> 7797.4096 | M40: =SUM(M36:M39) -> 7891.6973
A41: Current liabilities
A42: Financial Liabilities
A43: (i) Lease liabilities | F43: 1222 | G43: 1220 | H43: 1541 | I43: =H43*(1+I69) -> 1618.05 | J43: =I43*(1+J69) -> 1698.9525 | K43: =J43*(1+K69) -> 1783.9001 | L43: =K43*(1+L69) -> 1873.0951 | M43: =L43*(1+M69) -> 1966.7499
...

Sheet Colgate CF
A1: Colgate-Palmolive Cash Flow | F1: Forecasts
A3: (all data in ₹ Lakhs) | F3: 2026 | G3: 2027 | H3: 2028 | I3: 2029 | J3: 2030
A4: Operating Activities
A5: Profit Before Tax | F5: ='Colgate IS'!J20 -> 222635.81 | G5: ='Colgate IS'!K20 -> 244360.87 | H5: ='Colgate IS'!L20 -> 265010.98 | I5: ='Colgate IS'!M20 -> 287039.07 | J5: ='Colgate IS'!N20 -> 310674.32
A6: Depreciation | F6: ='Colgate IS'!J17 -> 13199.82 | G6: ='Colgate IS'!K17 -> 12397.518 | H6: ='Colgate IS'!L17 -> 11846.941 | I6: ='Colgate IS'!M17 -> 11546.608 | J6: ='Colgate IS'!N17 -> 11399.771
A7: Change in Working Capital
A8: Receivables | F8: ='Working Capital'!H6-'Working Capital'!I6 -> 1178.2594 | G8: ='Working Capital'!I6-'Working Capital'!J6 -> -1715.7392 | H8: ='Working Capital'!J6-'Working Capital'!K6 -> -1852.9984 | I8: ='Working Capital'!K6-'Working Capital'!L6 -> -2001.2383 | J8: ='Working Capital'!L6-'Working Capital'!M6 -> -2161.3373
A9: Inventory | F9: ='Working Capital'!H7-'Working Capital'!I7 -> -502.81512 | G9: ='Working Capital'!I7-'Working Capital'!J7 -> -3058.3052 | H9: ='Working Capital'!J7-'Working Capital'!K7 -> -3302.9696 | I9: ='Working Capital'!K7-'Working Capital'!L7 -> -3567.2072 | J9: ='Working Capital'!L7-'Working Capital'!M7 -> -3852.5838
A10: Payables | F10: ='Working Capital'!I8-'Working Capital'!H8 -> -8972.8802 | G10: ='Working Capital'!J8-'Working Capital'!I8 -> 6648.4896 | H10: ='Working Capital'!K8-'Working Capital'!J8 -> 7180.3688 | I10: ='Working Capital'!L8-'Working Capital'!K8 -> 7754.7983 | J10: ='Working Capital'!M8-'Working Capital'!L8 -> 8375.1821
A11: Cash generated before Tax | F11: =SUM(F5:F10) -> 227538.19 | G11: =SUM(G5:G10) -> 258632.83 | H11: =SUM(H5:H10) -> 278882.32 | I11: =SUM(I5:I10) -> 300772.03 | J11: =SUM(J5:J10) -> 324435.35
A12: Tax | F12: ='Colgate IS'!J21 -> 56772.132 | G12: ='Colgate IS'!K21 -> 62312.021 | H12: ='Colgate IS'!L21 -> 67577.8 | I12: ='Colgate IS'!M21 -> 73194.962 | J12: ='Colgate IS'!N21 -> 79221.952
A13: Net Cash from Operating Activities (A) | F13: =F11-F12 -> 170766.06 | G13: =G11-G12 -> 196320.81 | H13: =H11-H12 -> 211304.52 | I13: =I11-I12 -> 227577.07 | J13: =J11-J12 -> 245213.4
A15: Invensting Activities
A16: Capex | F16: ='Dep Capex'!I11 -> 8480.3987 | G16: ='Dep Capex'!J11 -> 9158.8306 | H16: ='Dep Capex'!K11 -> 10080.274 | I16: ='Dep Capex'!L11 -> 10682.86 | J16: ='Dep Capex'!M11 -> 11537.489
A17: Net Cash from Investing (B) | F17: =-F16 -> -8480.3987 | G17: =-G16 -> -9158.8306 | H17: =-H16 -> -10080.274 | I17: =-I16 -> -10682.86 | J17: =-J16 -> -11537.489
A19: Financing Activities
A20: PAT | F20: ='Colgate IS'!J22 -> 165863.68 | G20: ='Colgate IS'!K22 -> 182048.85 | H20: ='Colgate IS'!L22 -> 197433.18 | I20: ='Colgate IS'!M22 -> 213844.1 | J20: ='Colgate IS'!N22 -> 231452.37
A21: Dividend | F21: =F20*F32 -> 140984.13 | G21: =G20*G32 -> 154741.52 | H21: =H20*H32 -> 167818.2 | I21: =I20*I32 -> 181767.49 | J21: =J20*J32 -> 196734.51
A22: Net Cash from Financing (C) | F22: =-F21 -> -140984.13 | G22: =-G21 -> -154741.52 | H22: =-H21 -> -167818.2 | I22: =-I21 -> -181767.49 | J22: =-J21 -> -196734.51
A25: Net Change in Cash | F25: =F13+F17+F22 -> 21301.537 | G25: =G13+G17+G22 -> 32420.46 | H25: =H13+H17+H22 -> 33406.045 | I25: =I13+I17+I22 -> 35126.716 | J25: =J13+J17+J22 -> 36941.398
A26: Opening Cash | F26: ='Colgate BS'!H19 -> 66810 | G26: =F27 -> 88111.537 | H26: =G27 -> 120532 | I26: =H27 -> 153938.04 | J26: =I27 -> 189064.76
A27: Closing Cash | F27: =F25+F26 -> 88111.537 | G27: =G25+G26 -> 120532 | H27: =H25+H26 -> 153938.04 | I27: =I25+I26 -> 189064.76 | J27: =J25+J26 -> 226006.16
A32: Dividend | B32: (retained 15%) | F32: 0.85 | G32: 0.85 | H32: 0.85 | I32: 0.85 | J32: 0.85

Sheet Dep Capex
A1: Colgate-Palmolive Depreciation Capex | F1: Historicals | I1: Forecasts
A3: (all data in ₹ Lakhs) | F3: 2023 | G3: 2024 | H3: 2025 | I3: 2026 | J3: 2027 | K3: 2028 | L3: 2029 | M3: 2030
A5: PPE | F5: 96297 | G5: ='Colgate BS'!F6 -> 86179.92 | H5: ='Colgate BS'!G6 -> 79407 | I5: ='Colgate BS'!H6 -> 77646 | J5: =I13 -> 72926.579 | K5: =J13 -> 69687.891 | L5: =K13 -> 67921.223 | M5: =L13 -> 67057.475
A7: Dep | F7: ='Colgate IS'!G17 -> 17480.37 | G7: ='Colgate IS'!H17 -> 17151.05 | H7: ='Colgate IS'!I17 -> 16274 | I7: =I5*I8 -> 13199.82 | J7: =J5*J8 -> 12397.518 | K7: =K5*K8 -> 11846.941 | L7: =L5*L8 -> 11546.608 | M7: =M5*M8 -> 11399.771
A8: Depreciation as % of PPE | F8: =F7/F5 -> 0.18152559 | G8: =G7/G5 -> 0.19901446 | H8: =H7/H5 -> 0.20494415 | I8: 0.17 | J8: 0.17 | K8: 0.17 | L8: 0.17 | M8: 0.17
A10: Beginning PPE | F10: 96297 | G10: =F13 -> 86179.92 | H10: =G13 -> 79407 | I10: =H13 -> 77646 | J10: =I13 -> 72926.579 | K10: =J13 -> 69687.891 | L10: =K13 -> 67921.223 | M10: =L13 -> 67057.475
A11: Capital Expenditure | I11: =F20*'Colgate IS'!J4 -> 8480.3987 | J11: =F20*'Colgate IS'!K4 -> 9158.8306 | K11: ='Colgate IS'!L6*'Dep Capex'!F20 -> 10080.274 | L11: =F20*'Colgate IS'!M4 -> 10682.86 | M11: =F20*'Colgate IS'!N4 -> 11537.489
A12: Depreciation | F12: =F7 -> 17480.37 | G12: =G7 -> 17151.05 | H12: =H7 -> 16274 | I12: =I7 -> 13199.82 | J12: =J7 -> 12397.518 | K12: =K7 -> 11846.941 | L12: =L7 -> 11546.608 | M12: =M7 -> 11399.771
A13: Net PPE | F13: ='Colgate BS'!F6 -> 86179.92 | G13: ='Colgate BS'!G6 -> 79407 | H13: ='Colgate BS'!H6 -> 77646 | I13: =I10+I11-I12 -> 72926.579 | J13: =J10+J11-J12 -> 69687.891 | K13: =K10+K11-K12 -> 67921.223 | L13: =L10+L11-L12 -> 67057.475 | M13: =M10+M11-M12 -> 67195.193
A15: Capex | B15: 2023 | C15: 2024 | D15: 2025
B16: 7009 | C16: 7556 | D16: 7142
A17: Capex % as of Revenue
B18: =B16/'Colgate IS'!G6 -> 0.013275192 | C18: =C16/'Colgate IS'!H6 -> 0.013125005 | D18: =D16/'Colgate IS'!I6 -> 0.011558486
B20: For forecasts Average Capex has been taken as | F20: 0.013

Sheet Working Capital
A1: Colgate-Palmolive Working Capital | F1: Historicals | I1: Forecasts
A3: (all data in ₹ Lakhs) | F3: 2023 | G3: 2024 | H3: 2025 | I3: 2026 | J3: 2027 | K3: 2028 | L3: 2029 | M3: 2030
A5: Working Capital Balances
A6: Accounts Receivables | F6: ='Colgate BS'!F18 -> 15736.61 | G6: ='Colgate BS'!G18 -> 16739 | H6: ='Colgate BS'!H18 -> 22625 | I6: =I10/I14 -> 21446.741 | J6: =J10/J14 -> 23162.48 | K6: =K10/K14 -> 25015.478 | L6: =L10/L14 -> 27016.716 | M6: =M10/M14 -> 29178.054
A7: Inventory | F7: ='Colgate BS'!F16 -> 33544.96 | G7: ='Colgate BS'!G16 -> 29641 | H7: ='Colgate BS'!H16 -> 37726 | I7: =I11/I15 -> 38228.815 | J7: =J11/J15 -> 41287.12 | K7: =K11/K15 -> 44590.09 | L7: =L11/L15 -> 48157.297 | M7: =M11/M15 -> 52009.881
A8: Accounts Payables | F8: ='Colgate BS'!F44 -> 76112 | G8: ='Colgate BS'!G44 -> 88191 | H8: ='Colgate BS'!H44 -> 92079 | I8: =(I11/365)*I20 -> 83106.12 | J8: =(J11/365)*J20 -> 89754.609 | K8: =(K11/365)*K20 -> 96934.978 | L8: =(L11/365)*L20 -> 104689.78 | M8: =(M11/365)*M20 -> 113064.96
A10: Total Revenue | F10: ='Colgate IS'!G4 -> 522619.71 | G10: ='Colgate IS'!H4 -> 568043 | H10: ='Colgate IS'!I4 -> 604017 | I10: ='Colgate IS'!J4 -> 652338.36 | J10: ='Colgate IS'!K4 -> 704525.43 | K10: ='Colgate IS'!L4 -> 760887.46 | L10: ='Colgate IS'!M4 -> 821758.46 | M10: ='Colgate IS'!N4 -> 887499.14
A11: Operating Costs | F11: =SUM('Colgate IS'!G8:G9) -> 179026.44 | G11: =SUM('Colgate IS'!H8:H9) -> 170250.06 | H11: =SUM('Colgate IS'!I8:I9) -> 188897 | I11: =SUM('Colgate IS'!J8:J9) -> 202224.89 | J11: =SUM('Colgate IS'!K8:K9) -> 218402.88 | K11: =SUM('Colgate IS'!L8:L9) -> 235875.11 | L11: =SUM('Colgate IS'!M8:M9) -> 254745.12 | M11: =SUM('Colgate IS'!N8:N9) -> 275124.73
A13: Turnover Ratios
A14: Receivables turnover = (Sales / Accounts Receivables) | F14: =F10/F6 -> 33.210438 | G14: =G10/G6 -> 33.935301 | H14: =H10/H6 -> 26.696884 | I14: =365/I18 -> 30.416667 | J14: =365/J18 -> 30.416667 | K14: =365/K18 -> 30.416667 | L14: =365/L18 -> 30.416667 | M14: =365/M18 -> 30.416667
A15: Inventory turnover (COGS / Inventory) | F15: =F11/F7 -> 5.3369102 | G15: =G11/G7 -> 5.7437354 | H15: =H11/H7 -> 5.0070773 | I15: =365/I19 -> 5.2898551 | J15: =365/J19 -> 5.2898551 | K15: =365/K19 -> 5.2898551 | L15: =365/L19 -> 5.2898551 | M15: =365/M19 -> 5.2898551
A16: Payables turnover (COGS / Payables) | F16: =F11/F8 -> 2.3521447 | G16: =G11/G8 -> 1.9304698 | H16: =H11/H8 -> 2.0514667 | I16: =365/I20 -> 2.4333333 | J16: =365/J20 -> 2.4333333 | K16: =365/K20 -> 2.4333333 | L16: =365/L20 -> 2.4333333 | M16: =365/M20 -> 2.4333333
A18: Receivables collection period (365/receivables turnover) | F18: =365/F14 -> 10.990521 | G18: =365/G14 -> 10.755761 | H18: =365/H14 -> 13.672008 | I18: 12 | J18: 12 | K18: 12 | L18: 12 | M18: 12
A19: Inventory processing period (365/inventory turnover) | F19: =365/F15 -> 68.391632 | G19: =365/G15 -> 63.547496 | H19: =365/H15 -> 72.896817 | I19: 69 | J19: 69 | K19: 69 | L19: 69 | M19: 69
A20: Payment period (365/payables turnover) | F20: =365/F16 -> 155.17753 | G20: =365/G16 -> 189.07315 | H20: =365/H16 -> 177.92149 | I20: 150 | J20: 150 | K20: 150 | L20: 150 | M20: 150
A21: Cash Collection Cycle | F21: =F18+F19+-F20 -> -75.795373 | G21: =G18+G19+-G20 -> -114.76989 | H21: =H18+H19+-H20 -> -91.352662 | I21: =I18+I19-I20 -> -69 | J21: =J18+J19+-J20 -> -69 | K21: =K18+K19+-K20 -> -69 | L21: =L18+L19+-L20 -> -69 | M21: =M18+M19+-M20 -> -69

Sheet CWIP
A1: CWIP Schedule
B2: 2026 | C2: 2027 | D2: 2028 | E2: 2029 | F2: 2030
A3: Opening | B3: ='Colgate BS'!H7 -> 3841 | C3: =B9 -> 1272.0598 | D3: =C9 -> 1373.8246 | E3: =D9 -> 1512.041 | F3: =E9 -> 1602.429
A4: Capex | B4: ='Dep Capex'!I11 -> 8480.3987 | C4: ='Dep Capex'!J11 -> 9158.8306 | D4: ='Dep Capex'!K11 -> 10080.274 | E4: ='Dep Capex'!L11 -> 10682.86 | F4: ='Dep Capex'!M11 -> 11537.489
A5: Held(15%) | B5: 0.15 | C5: 0.15 | D5: 0.15 | E5: 0.15 | F5: 0.15
B6: =B4*B5 -> 1272.0598 | C6: =C4*C5 -> 1373.8246 | D6: =D4*D5 -> 1512.041 | E6: =E4*E5 -> 1602.429 | F6: =F4*F5 -> 1730.6233
A7: for capetalisation | B7: =B4-B6 -> 7208.3389 | C7: =C4-C6 -> 7785.006 | D7: =D4-D6 -> 8568.2326 | E7: =E4-E6 -> 9080.431 | F7: =F4-F6 -> 9806.8655
A8: Capetalised | B8: =B3+B7 -> 11049.339 | C8: =C3+C7 -> 9057.0658 | D8: =D3+D7 -> 9942.0571 | E8: =E3+E7 -> 10592.472 | F8: =F3+F7 -> 11409.294
A9: Closing | B9: =B6 -> 1272.0598 | C9: =C6 -> 1373.8246 | D9: =D6 -> 1512.041 | E9: =E6 -> 1602.429 | F9: =F6 -> 1730.6233

Sheet FA
A1: Financial Assets
A3: Non Current | B3: 2025 | C3: 2026 | D3: 2027 | E3: 2028 | F3: 2029 | G3: 20230
A4: (i) Loans | B4: ='Colgate BS'!H9 -> 120 | C4: =B4 -> 120 | D4: =C6 -> 126 | E4: =D6 -> 132.3 | F4: =E6 -> 138.915 | G4: =F6 -> 145.86075
A5: At 5% | C5: 0.05 | D5: 0.05 | E5: 0.05 | F5: 0.05 | G5: 0.05
C6: =C4*(1+C5) -> 126 | D6: =D4*(1+D5) -> 132.3 | E6: =E4*(1+E5) -> 138.915 | F6: =F4*(1+F5) -> 145.86075 | G6: =G4*(1+G5) -> 153.15379
A7: (ii) Other financial assets | B7: ='Colgate BS'!H10 -> 1783 | C7: =B7 -> 1783 | D7: =C9 -> 1872.15 | E7: =D9 -> 1965.7575 | F7: =E9 -> 2064.0454 | G7: =F9 -> 2167.2476
A8: at 5% | C8: 0.05 | D8: 0.05 | E8: 0.05 | F8: 0.05 | G8: 0.05
C9: =C7*(1+C8) -> 1872.15 | D9: =D7*(1+D8) -> 1965.7575 | E9: =E7*(1+E8) -> 2064.0454 | F9: =F7*(1+F8) -> 2167.2476 | G9: =G7*(1+G8) -> 2275.61

Sheet Equity
A1: Calculation of other Equity
B3: 2026 | C3: 2027 | D3: 2028 | E3: 2029 | F3: 2030
A4: Opening | B4: ='Colgate BS'!H30 -> 163727 | C4: =B8 -> 188606.55 | D4: =C8 -> 215913.88 | E4: =D8 -> 245528.86 | F4: =E8 -> 277605.47
A5: PAT | B5: ='Colgate IS'!J22 -> 165863.68 | C5: ='Colgate IS'!K22 -> 182048.85 | D5: ='Colgate IS'!L22 -> 197433.18 | E5: ='Colgate IS'!M22 -> 213844.1 | F5: ='Colgate IS'!N22 -> 231452.37
B6: 0.15 | C6: 0.15 | D6: 0.15 | E6: 0.15 | F6: 0.15
A7: Retained | B7: =B5*B6 -> 24879.552 | C7: =C5*C6 -> 27307.327 | D7: =D5*D6 -> 29614.977 | E7: =E5*E6 -> 32076.616 | F7: =F5*F6 -> 34717.855
A8: Closing other equity | B8: =B4+B7 -> 188606.55 | C8: =C4+C7 -> 215913.88 | D8: =D4+D7 -> 245528.86 | E8: =E4+E7 -> 277605.47 | F8: =F4+F7 -> 312323.33
